// MARK: - AutoCompletion
{% for type in types.protocols|annotated:"AutoCompletion" %}

extension {{ type.name }} {
    {% for method in type.methods %}
        {% if not method.isAsync and not method.throws %}
            {% continue %}
        {% endif %}

    {% for documentation in method.documentation %}
    /// {{ documentation }}
    {% endfor %}
    {% for key, value in method.attributes %}
    {{ value.first }}
    {% endfor %}
    @discardableResult
    public func {{ method.callName }}(
        {% for parameter in method.parameters %}
        {{ parameter.asSource }},
        {% endfor %}
        completion: @escaping @isolated(any) (Result<{{ method.returnTypeName.asSource }}, POFailure>) -> Void
    ) -> POCancellable {
        invoke(completion: completion) {
            try await {{ method.callName }}({% for parameter in method.parameters %}{% if parameter.argumentLabel %}{{ parameter.argumentLabel }}: {% endif %}{{ parameter.name }}{% if not forloop.last %}, {% endif %}{% endfor %})
        }
    }
    {% endfor %}
}
{% if forloop.last %}

/// Invokes given completion with a result of async operation.
private func invoke<T>(
    completion: @escaping (Result<T, POFailure>) -> Void,
    after operation: @escaping @isolated(any) () async throws -> T
) -> POCancellable {
    Task { @MainActor in
        do {
            let returnValue = try await operation()
            await completion(.success(returnValue))
        } catch let failure as POFailure {
            await completion(.failure(failure))
        } catch {
            let failure = POFailure(message: "Something went wrong.", code: .internal(.mobile), underlyingError: error)
            await completion(.failure(failure))
        }
    }
}
{% endif %}
{% endfor %}
